Workbook

Sheet 条件付き書式メモ
A1: AND関数やOR関数はINDIRECT関数と組み合わせると不具合があるので使用しない、論理和や論理積を組み合わせた式にする
A3: 工程内検査シート
A5: $A$11:$A$460 | B5: =IF(XLOOKUP(INDIRECT(ADDRESS(ROW(),1)),検査項目設定!$A$4:$A$103,検査項目設定!$M$4:$M$103,FALSE,1)="あり",TRUE,FALSE)
B7: XLOOKUPの結果が"あり"なら
B8: TRUE、それ以外はFALSE | C8: IF(XLOOKUP(INDIRECT(ADDRESS(ROW(),1)),検査項目設定!$A$4:$A$103,検査項目設定!$M$4:$M$103,FALSE,1)="あり",TRUE,FALSE)
A11: $L$10:$TZ$10 | B11: =INDIRECT(ADDRESS(ROW(),COLUMN()))="NG"
B13: 値がNG | C13: INDIRECT(ADDRESS(ROW(),COLUMN()))="NG"
A16: $L$11:$TZ$460 | B16: =(INDIRECT(ADDRESS(ROW(),COLUMN()))="NG")+(ISNUMBER(INDIRECT(ADDRESS(ROW(),COLUMN())))*(INDIRECT("J"&ROW()-MOD(ROW()+1,3))<>"")
B17: *((INDIRECT("J"&ROW()-MOD(ROW()+1,3))<INDIRECT(ADDRESS(ROW(),COLUMN())))+(INDIRECT("J"&ROW()-MOD(ROW()+1,3)+1)>INDIRECT(ADDRESS(ROW(),COLUMN())))))
B19: 値がNG | C19: (INDIRECT(ADDRESS(ROW(),COLUMN()))="NG")
B20: または | C20: +
B21: セルが数値 | C21: (ISNUMBER(INDIRECT(ADDRESS(ROW(),COLUMN())))
B22: かつ | C22: *
B23: 3行ごとに区切った時の1番目のJ列が
B24: 空白でない | C24: (INDIRECT("J"&ROW()-MOD(ROW()+1,3))<>"")
B25: かつ | C25: *
B26: 1番目のJ列の値を超えている | C26: ((INDIRECT("J"&ROW()-MOD(ROW()+1,3))<INDIRECT(ADDRESS(ROW(),COLUMN())))
B27: または | C27: +
B28: 2番目のJ列の値未満 | C28: (INDIRECT("J"&ROW()-MOD(ROW()+1,3)+1)>INDIRECT(ADDRESS(ROW(),COLUMN())))))
A31: 検査表入力シート
A33: 全体 | B33: =(ROW()>=12)*(COLUMN()>=3)*((ISNUMBER(INDIRECT(ADDRESS(ROW(),COLUMN()))))*((INDIRECT(ADDRESS(11,COLUMN()))>=INDIRECT(ADDRESS(ROW(),COLUMN())))
B34: +(INDIRECT(ADDRESS(10,COLUMN()))<=INDIRECT(ADDRESS(ROW(),COLUMN()))))+(INDIRECT(ADDRESS(ROW(),COLUMN()))="NG"))
B35: 12行目以降 | C35: (ROW()>=12)
B36: かつ | C36: *
B37: C列以降 | C37: (COLUMN()>=3)
B38: かつ | C38: *
B39: 該当セルが数値 | C39: ((ISNUMBER(INDIRECT(ADDRESS(ROW(),COLUMN()))))
B40: かつ | C40: *
B41: 同じ列の11行目の値以下 | C41: ((INDIRECT(ADDRESS(11,COLUMN()))>=INDIRECT(ADDRESS(ROW(),COLUMN())))
B42: または | C42: +
B43: 同じ列の10行目の値以上 | C43: (INDIRECT(ADDRESS(10,COLUMN()))<=INDIRECT(ADDRESS(ROW(),COLUMN()))))
B44: または | C44: +
B45: 該当セルの値が"NG" | C45: (INDIRECT(ADDRESS(ROW(),COLUMN()))="NG"))
A48: 検査表
A50: 複数箇所 | B50: =(INDIRECT(ADDRESS(ROW()-2-INDIRECT("C"&ROW()),COLUMN()))>=INDIRECT(ADDRESS(ROW(),COLUMN())))+(INDIRECT(ADDRESS(ROW()-3-INDIRECT("C"&ROW()),COLUMN()))<=INDIRECT(ADDRESS(ROW(),COLUMN())))
B52: 同列の上限値のセルを参照し、 | C52: (INDIRECT(ADDRESS(ROW()-2-INDIRECT("C"&ROW()),COLUMN()))
B53: そのセルの値以下 | C53: >=INDIRECT(ADDRESS(ROW(),COLUMN())))
B54: または | C54: +
B55: 同列の下限値のセルを参照し、 | C55: (INDIRECT(ADDRESS(ROW()-3-INDIRECT("C"&ROW()),COLUMN()))
B56: そのセルの値以上 | C56: <=INDIRECT(ADDRESS(ROW(),COLUMN())))

Sheet 集計1
B1: =COUNTA(B2:B101) -> 38 | N1: 1 | O1: {=IFERROR(IF(検査項目設定!B4:B103="","",検査項目設定!B4:B103),"")} -> 外径 | P1: {=IF($O1:$O100="","",IF(_xlfn.XLOOKUP($N$1:$N$100,検査項目設定!$A$4:$A$103,検査項目設定!C$4:C$103,"",0,1)="","",_xlfn.XLOOKUP($N$1:$N$100,検査項目設定!$A$4:$A$103,検査項目設定!C$4:C$103,"",0,1)))} | Q1: {=IF($O1:$O100="","",IF(_xlfn.XLOOKUP($N$1:$N$100,検査項目設定!$A$4:$A$103,検査項目設定!D$4:D$103,"",0,1)="","",_xlfn.XLOOKUP($N$1:$N$100,検査項目設定!$A$4:$A$103,検査項目設定!D$4:D$103,"",0,1)))} -> ﾃﾞｼﾞﾀﾙﾏｲｸﾛﾒｰﾀ | R1: {=IF($O1:$O100="","",IF(_xlfn.XLOOKUP($N$1:$N$100,検査項目設定!$A$4:$A$103,検査項目設定!E$4:E$103,"",0,1)="","",_xlfn.XLOOKUP($N$1:$N$100,検査項目設定!$A$4:$A$103,検査項目設定!E$4:E$103,"",0,1)))} -> φ | S1: {=IF($O1:$O100="","",IF(_xlfn.XLOOKUP($N$1:$N$100,検査項目設定!$A$4:$A$103,検査項目設定!F$4:F$103,"",0,1)="","",_xlfn.XLOOKUP($N$1:$N$100,検査項目設定!$A$4:$A$103,検査項目設定!F$4:F$103,"",0,1)))} -> 20.8 | T1: {=IF($O1:$O100="","",IF(_xlfn.XLOOKUP($N$1:$N$100,検査項目設定!$A$4:$A$103,検査項目設定!G$4:G$103,"",0,1)="","",_xlfn.XLOOKUP($N$1:$N$100,検査項目設定!$A$4:$A$103,検査項目設定!G$4:G$103,"",0,1)))} | U1: {=IF($O1:$O100="","",IF(_xlfn.XLOOKUP($N$1:$N$100,検査項目設定!$A$4:$A$103,検査項目設定!H$4:H$103,"",0,1)="","",_xlfn.XLOOKUP($N$1:$N$100,検査項目設定!$A$4:$A$103,検査項目設定!H$4:H$103,"",0,1)))} -> +0.1 | V1: {=IF($O1:$O100="","",IF(_xlfn.XLOOKUP($N$1:$N$100,検査項目設定!$A$4:$A$103,検査項目設定!I$4:I$103,"",0,1)="","",_xlfn.XLOOKUP($N$1:$N$100,検査項目設定!$A$4:$A$103,検査項目設定!I$4:I$103,"",0,1)))} -> -0.1 | W1: {=IF($O1:$O100="","",IF(_xlfn.XLOOKUP($N$1:$N$100,検査項目設定!$A$4:$A$103,検査項目設定!J$4:J$103,"",0,1)="","",_xlfn.XLOOKUP($N$1:$N$100,検査項目設定!$A$4:$A$103,検査項目設定!J$4:J$103,"",0,1)))} -> 片側 | ... Y1: {=IF($O1:$O100="","",IF(_xlfn.XLOOKUP($N$1:$N$100,検査項目設定!$A$4:$A$103,検査項目設定!L$4:L$103,"",0,1)="","",_xlfn.XLOOKUP($N$1:$N$100,検査項目設定!$A$4:$A$103,検査項目設定!L$4:L$103,"",0,1)))}
A2: {=_xlfn._xlws.FILTER($N$1:$Y$100,$O$1:$O$100<>"")} -> 1 | B2: 外径 | D2: ﾃﾞｼﾞﾀﾙﾏｲｸﾛﾒｰﾀ | E2: φ | F2: 20.8 | H2: +0.1 | I2: -0.1 | J2: 片側 | K2: 1 | M2: {=IF(F2:F101="","",IF(E2:E101="°",F2:F101&" "&E2:E101&" "&G2:G101,E2:E101&" "&F2:F101&" "&G2:G101))} -> φ 20.8 | N2: 2 | O2: 外径 | Q2: ﾃﾞｼﾞﾀﾙﾏｲｸﾛﾒｰﾀ | R2: φ | S2: 18.98 | U2: +0.01 | V2: -0.01 | W2: 片側 | X2: 1
A3: 2 | B3: 外径 | D3: ﾃﾞｼﾞﾀﾙﾏｲｸﾛﾒｰﾀ | E3: φ | F3: 18.98 | H3: +0.01 | I3: -0.01 | J3: 片側 | K3: 1 | M3: φ 18.98 | N3: 3 | O3: 外径 | Q3: ﾃﾞｼﾞﾀﾙﾏｲｸﾛﾒｰﾀ | R3: φ | S3: 18.5 | U3: +0.2 | V3: -0.2 | W3: 片側 | X3: 1
A4: 3 | B4: 外径 | D4: ﾃﾞｼﾞﾀﾙﾏｲｸﾛﾒｰﾀ | E4: φ | F4: 18.5 | H4: +0.2 | I4: -0.2 | J4: 片側 | K4: 1 | M4: φ 18.5 | N4: 4 | O4: ﾂﾊﾞ厚 | Q4: ﾃﾞｼﾞﾀﾙﾏｲｸﾛﾒｰﾀ | S4: 4.5 | U4: +0.1 | V4: -0.1 | W4: 片側 | X4: 1
A5: 4 | B5: ﾂﾊﾞ厚 | D5: ﾃﾞｼﾞﾀﾙﾏｲｸﾛﾒｰﾀ | F5: 4.5 | H5: +0.1 | I5: -0.1 | J5: 片側 | K5: 1 | M5: 4.5 | N5: 5 | O5: 長手 | Q5: ﾃﾞｼﾞﾀﾙﾀﾞｲﾔﾙｹﾞｰｼﾞ | S5: 1.6 | U5: +0.1 | V5: -0.1 | W5: 片側 | X5: 1
A6: 5 | B6: 長手 | D6: ﾃﾞｼﾞﾀﾙﾀﾞｲﾔﾙｹﾞｰｼﾞ | F6: 1.6 | H6: +0.1 | I6: -0.1 | J6: 片側 | K6: 1 | M6: 1.6 | N6: 6 | O6: 内長手 | P6: (計算) | Q6: ﾃﾞｼﾞﾀﾙﾀﾞｲﾔﾙｹﾞｰｼﾞ | S6: 11.5 | U6: +0.02 | V6: -0.02 | W6: 片側 | X6: 1
A7: 6 | B7: 内長手 | C7: (計算) | D7: ﾃﾞｼﾞﾀﾙﾀﾞｲﾔﾙｹﾞｰｼﾞ | F7: 11.5 | H7: +0.02 | I7: -0.02 | J7: 片側 | K7: 1 | M7: 11.5 | N7: 7 | O7: 内長手 | Q7: ﾃﾞｼﾞﾀﾙﾀﾞｲﾔﾙｹﾞｰｼﾞ | R7: ( | S7: 6.01 | T7: ) | U7: +1 | V7: -1 | W7: 片側 | X7: 1
A8: 7 | B8: 内長手 | D8: ﾃﾞｼﾞﾀﾙﾀﾞｲﾔﾙｹﾞｰｼﾞ | E8: ( | F8: 6.01 | G8: ) | H8: +1 | I8: -1 | J8: 片側 | K8: 1 | M8: ( 6.01 ) | N8: 8 | O8: 内長手 | Q8: ﾃﾞｼﾞﾀﾙﾀﾞｲﾔﾙｹﾞｰｼﾞ | S8: 1.0 | U8: +0.1 | V8: -0.1 | W8: 片側 | X8: 1
A9: 8 | B9: 内長手 | D9: ﾃﾞｼﾞﾀﾙﾀﾞｲﾔﾙｹﾞｰｼﾞ | F9: 1.0 | H9: +0.1 | I9: -0.1 | J9: 片側 | K9: 1 | M9: 1.0 | N9: 9 | O9: 内長手 | Q9: ﾃﾞｼﾞﾀﾙﾀﾞｲﾔﾙｹﾞｰｼﾞ | S9: 4.6 | U9: +0.1 | V9: -0.1 | W9: 片側 | X9: 1
A10: 9 | B10: 内長手 | D10: ﾃﾞｼﾞﾀﾙﾀﾞｲﾔﾙｹﾞｰｼﾞ | F10: 4.6 | H10: +0.1 | I10: -0.1 | J10: 片側 | K10: 1 | M10: 4.6 | N10: 10 | O10: ｸﾛｽ穴位置 | Q10: 工具顕微鏡 | S10: 2.5 | U10: +0.1 | V10: -0.1 | W10: 片側 | X10: 1
A11: 10 | B11: ｸﾛｽ穴位置 | D11: 工具顕微鏡 | F11: 2.5 | H11: +0.1 | I11: -0.1 | J11: 片側 | K11: 1 | M11: 2.5 | N11: 11 | O11: V溝位置 | Q11: 工具顕微鏡 | S11: 2.0 | U11: +0.1 | V11: -0.1 | W11: 片側 | X11: 1
A12: 11 | B12: V溝位置 | D12: 工具顕微鏡 | F12: 2.0 | H12: +0.1 | I12: -0.1 | J12: 片側 | K12: 1 | M12: 2.0 | N12: 12 | O12: V溝幅 | Q12: 工具顕微鏡 | S12: 1.0 | U12: +0.1 | V12: -0.1 | W12: 片側 | X12: 1
A13: 12 | B13: V溝幅 | D13: 工具顕微鏡 | F13: 1.0 | H13: +0.1 | I13: -0.1 | J13: 片側 | K13: 1 | M13: 1.0 | N13: 13 | O13: V溝角度 | Q13: 工具顕微鏡 | S13: 60 | T13: ° | U13: +1 | V13: -1 | W13: 片側 | X13: 1
A14: 13 | B14: V溝角度 | D14: 工具顕微鏡 | F14: 60 | G14: ° | H14: +1 | I14: -1 | J14: 片側 | K14: 1 | M14: 60 ° | N14: 14 | O14: ﾃｰﾊﾟｰ | Q14: 工具顕微鏡 | S14: 33 | T14: ° | U14: +1 | V14: -1 | W14: 片側 | X14: 1
A15: 14 | B15: ﾃｰﾊﾟｰ | D15: 工具顕微鏡 | F15: 33 | G15: ° | H15: +1 | I15: -1 | J15: 片側 | K15: 1 | M15: 33 ° | N15: 15 | O15: C面取り | P15: (φ18.98) | Q15: 工具顕微鏡 | R15: C | S15: 0.1 | U15: +0.1 | V15: -0.1 | W15: 片側 | X15: 1
A16: 15 | B16: C面取り | C16: (φ18.98) | D16: 工具顕微鏡 | E16: C | F16: 0.1 | H16: +0.1 | I16: -0.1 | J16: 片側 | K16: 1 | M16: C 0.1 | N16: 16 | O16: C内面取り | P16: (φ18.2) | Q16: 工具顕微鏡 | R16: C | S16: 0.1 | U16: +0.1 | V16: -0.1 | W16: 片側 | X16: 1
A17: 16 | B17: C内面取り | C17: (φ18.2) | D17: 工具顕微鏡 | E17: C | F17: 0.1 | H17: +0.1 | I17: -0.1 | J17: 片側 | K17: 1 | M17: C 0.1 | N17: 17 | O17: 指示なき角部 | Q17: 工具顕微鏡 | R17: C or R | S17: 0.2 | U17: +0.1 | V17: -0.1 | W17: 片側 | X17: 1
A18: 17 | B18: 指示なき角部 | D18: 工具顕微鏡 | E18: C or R | F18: 0.2 | H18: +0.1 | I18: -0.1 | J18: 片側 | K18: 1 | M18: C or R 0.2 | N18: 18 | O18: 隅R | P18: (φ18.98) | Q18: 形状測定機 | R18: R | S18: 0.2 | T18: 以下 | U18: 0 | V18: -0.2 | W18: 片側 | X18: 1
A19: 18 | B19: 隅R | C19: (φ18.98) | D19: 形状測定機 | E19: R | F19: 0.2 | G19: 以下 | H19: 0 | I19: -0.2 | J19: 片側 | K19: 1 | M19: R 0.2 以下 | N19: 19 | O19: 内径角R | P19: (φ13.0右側) | Q19: 形状測定機 | R19: R | S19: 1.0 | U19: +0.1 | V19: -0.1 | W19: 片側 | X19: 1
A20: 19 | B20: 内径角R | C20: (φ13.0右側) | D20: 形状測定機 | E20: R | F20: 1.0 | H20: +0.1 | I20: -0.1 | J20: 片側 | K20: 1 | M20: R 1.0 | N20: 20 | O20: 内ﾃｰﾊﾟｰ | Q20: 形状測定機 | S20: 120 | T20: ° | U20: +1 | V20: -1 | W20: 片側 | X20: 1
A21: 20 | B21: 内ﾃｰﾊﾟｰ | D21: 形状測定機 | F21: 120 | G21: ° | H21: +1 | I21: -1 | J21: 片側 | K21: 1 | M21: 120 ° | N21: 21 | O21: 粗さ | P21: (120°) | Q21: 形状測定機 | R21: Rmax | S21: 6.3 | U21: 0 | V21: -6.3 | W21: 片側 | X21: 1
A22: 21 | B22: 粗さ | C22: (120°) | D22: 形状測定機 | E22: Rmax | F22: 6.3 | H22: 0 | I22: -6.3 | J22: 片側 | K22: 1 | M22: Rmax 6.3 | N22: 22 | O22: 内径角R | P22: (φ13.0左側) | Q22: 形状測定機 | R22: R | S22: 0.05 | U22: +0.05 | V22: -0.05 | W22: 片側 | X22: 1
A23: 22 | B23: 内径角R | C23: (φ13.0左側) | D23: 形状測定機 | E23: R | F23: 0.05 | H23: +0.05 | I23: -0.05 | J23: 片側 | K23: 1 | M23: R 0.05 | N23: 23 | O23: 内長手 | P23: (架空点) | Q23: 形状測定機 | S23: 1.0 | U23: +0.025 | V23: -0.025 | W23: 片側 | X23: 1
A24: 23 | B24: 内長手 | C24: (架空点) | D24: 形状測定機 | F24: 1.0 | H24: +0.025 | I24: -0.025 | J24: 片側 | K24: 1 | M24: 1.0 | N24: 24 | O24: 粗さ | P24: (端面) | Q24: 形状測定機 | R24: Rmax | S24: 6.3 | U24: 0 | V24: -6.3 | W24: 片側 | X24: 1
A25: 24 | B25: 粗さ | C25: (端面) | D25: 形状測定機 | E25: Rmax | F25: 6.3 | H25: 0 | I25: -6.3 | J25: 片側 | K25: 1 | M25: Rmax 6.3 | N25: 25 | O25: 粗さ | P25: (φ13.0) | Q25: 形状測定機 | R25: Rmax | S25: 6.3 | U25: 0 | V25: -6.3 | W25: 片側 | X25: 1
A26: 25 | B26: 粗さ | C26: (φ13.0) | D26: 形状測定機 | E26: Rmax | F26: 6.3 | H26: 0 | I26: -6.3 | J26: 片側 | K26: 1 | M26: Rmax 6.3 | N26: 26 | O26: 全体粗さ | Q26: 形状測定機 | R26: Rmax | S26: 12.5 | U26: 0 | V26: -12.5 | W26: 片側 | X26: 1
A27: 26 | B27: 全体粗さ | D27: 形状測定機 | E27: Rmax | F27: 12.5 | H27: 0 | I27: -12.5 | J27: 片側 | K27: 1 | M27: Rmax 12.5 | N27: 27 | O27: 指示なき隅部 | Q27: 工具顕微鏡 | R27: C or R | S27: 0.2 | U27: +0.1 | V27: -0.1 | W27: 片側 | X27: 1
A28: 27 | B28: 指示なき隅部 | D28: 工具顕微鏡 | E28: C or R | F28: 0.2 | H28: +0.1 | I28: -0.1 | J28: 片側 | K28: 1 | M28: C or R 0.2 | N28: 28 | O28: 内径 | P28: (ｶｯﾄなし品) | Q28: ﾎﾞﾜｰｽﾞﾏｲｸﾛ | R28: φ | S28: 17.5 | U28: +0.1 | V28: -0.1 | W28: 片側 | X28: 1
A29: 28 | B29: 内径 | C29: (ｶｯﾄなし品) | D29: ﾎﾞﾜｰｽﾞﾏｲｸﾛ | E29: φ | F29: 17.5 | H29: +0.1 | I29: -0.1 | J29: 片側 | K29: 1 | M29: φ 17.5 | N29: 29 | O29: 内径 | Q29: ﾎﾞﾜｰｽﾞﾏｲｸﾛ | R29: φ | S29: 18.2 | U29: +0.1 | V29: -0.1 | W29: 片側 | X29: 1
A30: 29 | B30: 内径 | D30: ﾎﾞﾜｰｽﾞﾏｲｸﾛ | E30: φ | F30: 18.2 | H30: +0.1 | I30: -0.1 | J30: 片側 | K30: 1 | M30: φ 18.2 | N30: 30 | O30: 内径 | P30: (狙い値15.9) | Q30: ﾎﾞﾜｰｽﾞﾏｲｸﾛ | R30: φ | S30: 15.9 | U30: +0.025 | V30: -0.02 | W30: 片側 | X30: 1
A31: 30 | B31: 内径 | C31: (狙い値15.9) | D31: ﾎﾞﾜｰｽﾞﾏｲｸﾛ | E31: φ | F31: 15.9 | H31: +0.025 | I31: -0.02 | J31: 片側 | K31: 1 | M31: φ 15.9 | N31: 31 | O31: 内径 | Q31: ﾎﾞﾜｰｽﾞﾏｲｸﾛ | R31: φ | S31: 13.0 | U31: +0.05 | V31: 0 | W31: 片側 | X31: 1
A32: 31 | B32: 内径 | D32: ﾎﾞﾜｰｽﾞﾏｲｸﾛ | E32: φ | F32: 13.0 | H32: +0.05 | I32: 0 | J32: 片側 | K32: 1 | M32: φ 13.0 | N32: 32 | O32: ｸﾛｽ穴 | Q32: ﾋﾟﾝｹﾞｰｼﾞ | R32: φ | S32: 0.6 | U32: +0.05 | V32: -0.05 | W32: 片側 | X32: 1
A33: 32 | B33: ｸﾛｽ穴 | D33: ﾋﾟﾝｹﾞｰｼﾞ | E33: φ | F33: 0.6 | H33: +0.05 | I33: -0.05 | J33: 片側 | K33: 1 | M33: φ 0.6 | N33: 33 | O33: 円筒度 | P33: (φ18.98) | Q33: 真円度測定機 | S33: 0.02 | U33: 0 | V33: -0.02 | W33: 片側 | X33: 1
A34: 33 | B34: 円筒度 | C34: (φ18.98) | D34: 真円度測定機 | F34: 0.02 | H34: 0 | I34: -0.02 | J34: 片側 | K34: 1 | M34: 0.02 | N34: 34 | O34: 真円度 | P34: (φ13.0) | Q34: 真円度測定機 | S34: 0.02 | U34: 0 | V34: -0.02 | W34: 片側 | X34: 1
A35: 34 | B35: 真円度 | C35: (φ13.0) | D35: 真円度測定機 | F35: 0.02 | H35: 0 | I35: -0.02 | J35: 片側 | K35: 1 | M35: 0.02 | N35: 35 | O35: 同軸度 | P35: (φ13.0/A) | Q35: 真円度測定機 | R35: φ | S35: 0.02 | U35: 0 | V35: -0.02 | W35: 片側 | X35: 1
A36: 35 | B36: 同軸度 | C36: (φ13.0/A) | D36: 真円度測定機 | E36: φ | F36: 0.02 | H36: 0 | I36: -0.02 | J36: 片側 | K36: 1 | M36: φ 0.02 | N36: 36 | O36: 平面度 | P36: (長手1.6) | Q36: 真円度測定機 | S36: 0.02 | U36: 0 | V36: -0.02 | W36: 片側 | X36: 1
A37: 36 | B37: 平面度 | C37: (長手1.6) | D37: 真円度測定機 | F37: 0.02 | H37: 0 | I37: -0.02 | J37: 片側 | K37: 1 | M37: 0.02 | N37: 37 | O37: 直角度 | P37: (長手1.6/A) | Q37: 真円度測定機 | S37: 0.02 | U37: 0 | V37: -0.02 | W37: 片側 | X37: 1
A38: 37 | B38: 直角度 | C38: (長手1.6/A) | D38: 真円度測定機 | F38: 0.02 | H38: 0 | I38: -0.02 | J38: 片側 | K38: 1 | M38: 0.02 | N38: 38 | O38: 振れ | P38: (120°/A) | Q38: 真円度測定機 | S38: 0.02 | U38: 0 | V38: -0.02 | W38: 片側 | X38: 1
A39: 38 | B39: 振れ | C39: (120°/A) | D39: 真円度測定機 | F39: 0.02 | H39: 0 | I39: -0.02 | J39: 片側 | K39: 1 | M39: 0.02 | N39: 39
N40: 40
...

Sheet 集計2
A1: {=_xlfn._xlws.FILTER($N$1:$Y$100,$O$1:$O$100<>"")} -> #VALUE! | M1: {=IF(F1:F100="","",IF(E1:E100="°",F1:F100&" "&E1:E100&" "&G1:G100,E1:E100&" "&F1:F100&" "&G1:G100))} | N1: 1 | O1: {=IFERROR(IF((検査項目設定!B4:B103="")+(検査項目設定!L4:L103<>TRUE),"",検査項目設定!B4:B103),"")} | P1: {=IF($O1:$O100="","",IF(_xlfn.XLOOKUP($N$1:$N$100,検査項目設定!$A$4:$A$103,検査項目設定!C$4:C$103,"",0,1)="","",_xlfn.XLOOKUP($N$1:$N$100,検査項目設定!$A$4:$A$103,検査項目設定!C$4:C$103,"",0,1)))} | Q1: {=IF($O1:$O100="","",IF(_xlfn.XLOOKUP($N$1:$N$100,検査項目設定!$A$4:$A$103,検査項目設定!D$4:D$103,"",0,1)="","",_xlfn.XLOOKUP($N$1:$N$100,検査項目設定!$A$4:$A$103,検査項目設定!D$4:D$103,"",0,1)))} | R1: {=IF($O1:$O100="","",IF(_xlfn.XLOOKUP($N$1:$N$100,検査項目設定!$A$4:$A$103,検査項目設定!E$4:E$103,"",0,1)="","",_xlfn.XLOOKUP($N$1:$N$100,検査項目設定!$A$4:$A$103,検査項目設定!E$4:E$103,"",0,1)))} | S1: {=IF($O1:$O100="","",IF(_xlfn.XLOOKUP($N$1:$N$100,検査項目設定!$A$4:$A$103,検査項目設定!F$4:F$103,"",0,1)="","",_xlfn.XLOOKUP($N$1:$N$100,検査項目設定!$A$4:$A$103,検査項目設定!F$4:F$103,"",0,1)))} | T1: {=IF($O1:$O100="","",IF(_xlfn.XLOOKUP($N$1:$N$100,検査項目設定!$A$4:$A$103,検査項目設定!G$4:G$103,"",0,1)="","",_xlfn.XLOOKUP($N$1:$N$100,検査項目設定!$A$4:$A$103,検査項目設定!G$4:G$103,"",0,1)))} | U1: {=IF($O1:$O100="","",IF(_xlfn.XLOOKUP($N$1:$N$100,検査項目設定!$A$4:$A$103,検査項目設定!H$4:H$103,"",0,1)="","",_xlfn.XLOOKUP($N$1:$N$100,検査項目設定!$A$4:$A$103,検査項目設定!H$4:H$103,"",0,1)))} | V1: {=IF($O1:$O100="","",IF(_xlfn.XLOOKUP($N$1:$N$100,検査項目設定!$A$4:$A$103,検査項目設定!I$4:I$103,"",0,1)="","",_xlfn.XLOOKUP($N$1:$N$100,検査項目設定!$A$4:$A$103,検査項目設定!I$4:I$103,"",0,1)))} | W1: {=IF($O1:$O100="","",IF(_xlfn.XLOOKUP($N$1:$N$100,検査項目設定!$A$4:$A$103,検査項目設定!J$4:J$103,"",0,1)="","",_xlfn.XLOOKUP($N$1:$N$100,検査項目設定!$A$4:$A$103,検査項目設定!J$4:J$103,"",0,1)))} | ... Y1: {=IF($O1:$O100="","",IF(_xlfn.XLOOKUP($N$1:$N$100,検査項目設定!$A$4:$A$103,検査項目設定!L$4:L$103,"",0,1)="","",_xlfn.XLOOKUP($N$1:$N$100,検査項目設定!$A$4:$A$103,検査項目設定!L$4:L$103,"",0,1)))}
N2: 2
N3: 3
N4: 4
N5: 5
N6: 6
N7: 7
N8: 8
N9: 9
N10: 10
N11: 11
N12: 12
N13: 13
... N100: 100

Sheet 集計3
A1: =検査表!AV8 -> D-2
C2: 1 | D2: 2 | E2: 3 | F2: 4 | G2: 5 | H2: 6 | I2: 7 | J2: 8 | K2: 9 | L2: 10 | M2: 11 | N2: 12 | O2: 13 | P2: 14 | Q2: 15 | R2: 16 | S2: 17 | T2: 18 | U2: 19 | V2: 20 | W2: 21 | X2: 22 | Y2: 23 | Z2: 24 | AA2: 25 | AB2: 26 | AC2: 27 | AD2: 28 | AE2: 29 | AF2: 30 | AG2: 31 | AH2: 32 | AI2: 33 | AJ2: 34 | AK2: 35 | AL2: 36 | AM2: 37 | AN2: 38 | AO2: 39 | AP2: 40 | AQ2: 41 | AR2: 42 | AS2: 43 | AT2: 44 | AU2: 45 | AV2: 46 | AW2: 47 | AX2: 48 | AY2: 49 | AZ2: 50 | BA2: 51 | BB2: 52 | BC2: 53 | BD2: 54 | BE2: 55 | BF2: 56 | BG2: 57 | BH2: 58 | BI2: 59 | BJ2: 60 | BK2: 61 | BL2: 62 | BM2: 63 | BN2: 64 | BO2: 65 | BP2: 66 | BQ2: 67 | BR2: 68 | BS2: 69 | BT2: 70 | BU2: 71 | BV2: 72 | BW2: 73 | BX2: 74 | BY2: 75 | BZ2: 76 | CA2: 77 | CB2: 78 | CC2: 79 | CD2: 80 | CE2: 81 | CF2: 82 | CG2: 83 | CH2: 84 | CI2: 85 | CJ2: 86 | CK2: 87 | CL2: 88 | CM2: 89 | CN2: 90 | CO2: 91 | CP2: 92 | CQ2: 93 | CR2: 94 | CS2: 95 | CT2: 96 | CU2: 97 | CV2: 98 | CW2: 99 | CX2: 100
A3: =IF(検査表!AV6="","",検査表!AV6) | B3: {=_xlfn.XLOOKUP(A3,_xlfn._xlws.FILTER(INDIRECT("'"&$A$1&"'!$B$12:$B$8196"),MOD(ROW(INDIRECT("'"&$A$1&"'!$B$12:$B$8196")),3)=0,1),_xlfn._xlws.FILTER(ROW(INDIRECT("'"&$A$1&"'!$B$12:$B$8196")),MOD(ROW(INDIRECT("'"&$A$1&"'!$B$12:$B$8196")),3)=0,1),"",0,1)} | C3: {=IFERROR(IF(検査表!AV7<1,"",_xlfn._xlws.FILTER(INDIRECT("'"&$A$1&"'!$C$"&$B3&":$CX$"&$B3),INDIRECT("'"&$A$1&"'!$C$2:$CX$2")<>"")),"")}
A4: {=IFERROR(IF(INDIRECT("'"&$A$1&"'!"&ADDRESS(B4,2))="","",INDIRECT("'"&$A$1&"'!"&ADDRESS(B4,2))),"")} | B4: =IFERROR(B3+1,"") | C4: {=IFERROR(IF(検査表!AV7<2,"",_xlfn._xlws.FILTER(INDIRECT("'"&$A$1&"'!$C$"&$B4&":$CX$"&$B4),INDIRECT("'"&$A$1&"'!$C$2:$CX$2")<>"")),"")}
A5: {=IFERROR(IF(INDIRECT("'"&$A$1&"'!"&ADDRESS(B4,1))="","",INDIRECT("'"&$A$1&"'!"&ADDRESS(B4,1))),"")} | B5: =IFERROR(B3+2,"") | C5: {=IFERROR(IF(検査表!AV7<3,"",_xlfn._xlws.FILTER(INDIRECT("'"&$A$1&"'!$C$"&$B5&":$CX$"&$B5),INDIRECT("'"&$A$1&"'!$C$2:$CX$2")<>"")),"")}
A6: =IF(検査表!AW6="","",検査表!AW6) | B6: {=_xlfn.XLOOKUP(A6,_xlfn._xlws.FILTER(INDIRECT("'"&$A$1&"'!$B$12:$B$8196"),MOD(ROW(INDIRECT("'"&$A$1&"'!$B$12:$B$8196")),3)=0,1),_xlfn._xlws.FILTER(ROW(INDIRECT("'"&$A$1&"'!$B$12:$B$8196")),MOD(ROW(INDIRECT("'"&$A$1&"'!$B$12:$B$8196")),3)=0,1),"",0,1)} | C6: {=IFERROR(IF(検査表!AW7<1,"",_xlfn._xlws.FILTER(INDIRECT("'"&$A$1&"'!$C$"&$B6&":$CX$"&$B6),INDIRECT("'"&$A$1&"'!$C$2:$CX$2")<>"")),"")}
A7: {=IFERROR(IF(INDIRECT("'"&$A$1&"'!"&ADDRESS(B7,2))="","",INDIRECT("'"&$A$1&"'!"&ADDRESS(B7,2))),"")} | B7: =IFERROR(B6+1,"") | C7: {=IFERROR(IF(検査表!AW7<2,"",_xlfn._xlws.FILTER(INDIRECT("'"&$A$1&"'!$C$"&$B7&":$CX$"&$B7),INDIRECT("'"&$A$1&"'!$C$2:$CX$2")<>"")),"")}
A8: {=IFERROR(IF(INDIRECT("'"&$A$1&"'!"&ADDRESS(B7,1))="","",INDIRECT("'"&$A$1&"'!"&ADDRESS(B7,1))),"")} | B8: =IFERROR(B6+2,"") | C8: {=IFERROR(IF(検査表!AW7<3,"",_xlfn._xlws.FILTER(INDIRECT("'"&$A$1&"'!$C$"&$B8&":$CX$"&$B8),INDIRECT("'"&$A$1&"'!$C$2:$CX$2")<>"")),"")}
A9: =IF(検査表!AX6="","",検査表!AX6) | B9: {=_xlfn.XLOOKUP(A9,_xlfn._xlws.FILTER(INDIRECT("'"&$A$1&"'!$B$12:$B$8196"),MOD(ROW(INDIRECT("'"&$A$1&"'!$B$12:$B$8196")),3)=0,1),_xlfn._xlws.FILTER(ROW(INDIRECT("'"&$A$1&"'!$B$12:$B$8196")),MOD(ROW(INDIRECT("'"&$A$1&"'!$B$12:$B$8196")),3)=0,1),"",0,1)} | C9: {=IFERROR(IF(検査表!AX7<1,"",_xlfn._xlws.FILTER(INDIRECT("'"&$A$1&"'!$C$"&$B9&":$CX$"&$B9),INDIRECT("'"&$A$1&"'!$C$2:$CX$2")<>"")),"")}
A10: {=IFERROR(IF(INDIRECT("'"&$A$1&"'!"&ADDRESS(B10,2))="","",INDIRECT("'"&$A$1&"'!"&ADDRESS(B10,2))),"")} | B10: =IFERROR(B9+1,"") | C10: {=IFERROR(IF(検査表!AX7<2,"",_xlfn._xlws.FILTER(INDIRECT("'"&$A$1&"'!$C$"&$B10&":$CX$"&$B10),INDIRECT("'"&$A$1&"'!$C$2:$CX$2")<>"")),"")}
A11: {=IFERROR(IF(INDIRECT("'"&$A$1&"'!"&ADDRESS(B10,1))="","",INDIRECT("'"&$A$1&"'!"&ADDRESS(B10,1))),"")} | B11: =IFERROR(B9+2,"") | C11: {=IFERROR(IF(検査表!AX7<3,"",_xlfn._xlws.FILTER(INDIRECT("'"&$A$1&"'!$C$"&$B11&":$CX$"&$B11),INDIRECT("'"&$A$1&"'!$C$2:$CX$2")<>"")),"")}
A12: =IF(検査表!AY6="","",検査表!AY6) | B12: {=_xlfn.XLOOKUP(A12,_xlfn._xlws.FILTER(INDIRECT("'"&$A$1&"'!$B$12:$B$8196"),MOD(ROW(INDIRECT("'"&$A$1&"'!$B$12:$B$8196")),3)=0,1),_xlfn._xlws.FILTER(ROW(INDIRECT("'"&$A$1&"'!$B$12:$B$8196")),MOD(ROW(INDIRECT("'"&$A$1&"'!$B$12:$B$8196")),3)=0,1),"",0,1)} | C12: {=IFERROR(IF(検査表!AY7<1,"",_xlfn._xlws.FILTER(INDIRECT("'"&$A$1&"'!$C$"&$B12&":$CX$"&$B12),INDIRECT("'"&$A$1&"'!$C$2:$CX$2")<>"")),"")}
A13: {=IFERROR(IF(INDIRECT("'"&$A$1&"'!"&ADDRESS(B13,2))="","",INDIRECT("'"&$A$1&"'!"&ADDRESS(B13,2))),"")} | B13: =IFERROR(B12+1,"") | C13: {=IFERROR(IF(検査表!AY7<2,"",_xlfn._xlws.FILTER(INDIRECT("'"&$A$1&"'!$C$"&$B13&":$CX$"&$B13),INDIRECT("'"&$A$1&"'!$C$2:$CX$2")<>"")),"")}
A14: {=IFERROR(IF(INDIRECT("'"&$A$1&"'!"&ADDRESS(B13,1))="","",INDIRECT("'"&$A$1&"'!"&ADDRESS(B13,1))),"")} | B14: =IFERROR(B12+2,"") | C14: {=IFERROR(IF(検査表!AY7<3,"",_xlfn._xlws.FILTER(INDIRECT("'"&$A$1&"'!$C$"&$B14&":$CX$"&$B14),INDIRECT("'"&$A$1&"'!$C$2:$CX$2")<>"")),"")}
B16: 1 | C16: {=IFERROR(_xlfn._xlws.FILTER(C$3:C$14,(C$3:C$14<>"")*(C$3:C$14<>0)),"")} | D16: {=IFERROR(_xlfn._xlws.FILTER(D$3:D$14,(D$3:D$14<>"")*(D$3:D$14<>0)),"")} | E16: {=IFERROR(_xlfn._xlws.FILTER(E$3:E$14,(E$3:E$14<>"")*(E$3:E$14<>0)),"")} | F16: {=IFERROR(_xlfn._xlws.FILTER(F$3:F$14,(F$3:F$14<>"")*(F$3:F$14<>0)),"")} | G16: {=IFERROR(_xlfn._xlws.FILTER(G$3:G$14,(G$3:G$14<>"")*(G$3:G$14<>0)),"")} | H16: {=IFERROR(_xlfn._xlws.FILTER(H$3:H$14,(H$3:H$14<>"")*(H$3:H$14<>0)),"")} | I16: {=IFERROR(_xlfn._xlws.FILTER(I$3:I$14,(I$3:I$14<>"")*(I$3:I$14<>0)),"")} | J16: {=IFERROR(_xlfn._xlws.FILTER(J$3:J$14,(J$3:J$14<>"")*(J$3:J$14<>0)),"")} | ... CX16: {=IFERROR(_xlfn._xlws.FILTER(CX$3:CX$14,(CX$3:CX$14<>"")*(CX$3:CX$14<>0)),"")}
B17: 2
B18: 3
B19: 4
B20: 5
B21: 6
B22: 7
B23: 8
B24: 9
B25: 10

Sheet 工程内検査シート
